2020-05-06 01:33:23,418	ERROR scripts.py:416 -- Error shutting down jupyter
Traceback (most recent call last):
  File "/home/rmlans/anaconda3/envs/tf2_env/lib/python3.6/site-packages/ray/scripts/scripts.py", line 408, in stop
    str(server["pid"]) for server in list_running_servers()
  File "/home/rmlans/anaconda3/envs/tf2_env/lib/python3.6/site-packages/ray/scripts/scripts.py", line 408, in <listcomp>
    str(server["pid"]) for server in list_running_servers()
  File "/home/rmlans/anaconda3/envs/tf2_env/lib/python3.6/site-packages/notebook/notebookapp.py", line 1767, in list_running_servers
    info = json.load(f)
  File "/home/rmlans/anaconda3/envs/tf2_env/lib/python3.6/json/__init__.py", line 299, in load
    parse_constant=parse_constant, object_pairs_hook=object_pairs_hook, **kw)
  File "/home/rmlans/anaconda3/envs/tf2_env/lib/python3.6/json/__init__.py", line 354, in loads
    return _default_decoder.decode(s)
  File "/home/rmlans/anaconda3/envs/tf2_env/lib/python3.6/json/decoder.py", line 339, in decode
    obj, end = self.raw_decode(s, idx=_w(s, 0).end())
  File "/home/rmlans/anaconda3/envs/tf2_env/lib/python3.6/json/decoder.py", line 357, in raw_decode
    raise JSONDecodeError("Expecting value", s, err.value) from None
json.decoder.JSONDecodeError: Expecting value: line 2 column 1 (char 1)
